<?xml version="1.0"?>	
<robot name="robot">

  <!--BASE FOOTPRINT-->
  <link name="base_footprint" />

  <!--===== Defining all colours here =====-->
  <material name="Orange">
    <color rgba="0.5 0.2 0.0 1" />
  </material>
  <material name="Yellow">
    <color rgba="0.5 0.5 0.0 1" />
  </material>
  <material name="Red">
    <color rgba="0.5 0.0 0.0 1" />
  </material>
  <material name="Blue">
    <color rgba="0.0 0.0 0.4 1" />
  </material>
  <material name="Green">
    <color rgba="0.0 0.4 0.0 1" />
  </material>


  <!--========================================== BASE LINK ==========================================-->
  <link name="base_link">
    <inertial>
      <origin xyz="0 0 0" rpy="0 0 0" />
      <mass value="70.0" />
      <inertia ixx="0.079945" ixy="0.00012078" ixz="0.00015606" iyy="0.068406" iyz="-0.0049053" izz="0.12343" />
    </inertial>
  <visual>
    <!--origin xyz="0 0 0" rpy="0 0 -1.57" /-->
    <origin xyz="0 0 -0.015" rpy="0 0 -1.57" />
    <geometry>
      <!--cylinder length="0.007" radius="0.13"/-->
      <mesh filename="package://my_robot_model/urdf/meshes/Base_Plate.stl" scale="0.001 0.001 0.001"/>
    </geometry>
    <material name="Blue" />
  </visual>
  <collision>
    <!--origin xyz="0 0 0" rpy="0 0 -1.57" /-->
    <origin xyz="0 0 -0.015" rpy="0 0 -1.57" />
    <geometry>
      <!--cylinder length="0.007" radius="0.13"/-->
      <mesh filename="package://my_robot_model/urdf/meshes/Base_Plate.stl" scale="0.001 0.001 0.001"/>
    </geometry>
  </collision>
  </link>


  <!--========================================== BASE JOINT ==========================================-->
  <joint name="base_joint" type="fixed">
    <origin xyz="0 0 0.0335" rpy="0 0 0" />
    <parent link="base_footprint" />
    <child link="base_link" />
    <axis xyz="0 0 0" />
  </joint>


  <!--========================================== ROBOT BODY LINK==========================================-->
  <link name="robot_body_link">
    <inertial>
      <origin xyz="0 0 0" rpy="0 0 0" />
      <mass value="70.0" />
      <inertia ixx="0.079945" ixy="0.00012078" ixz="0.00015606" iyy="0.068406" iyz="-0.0049053" izz="0.12343" />
    </inertial>
  <visual>
    <!--origin xyz="0 0 0" rpy="0 0 0" /-->
    <origin xyz="0.0 0 -0.19125" rpy="0 0 -1.57" />
    <geometry>
      <!--cylinder length="0.35" radius="0.13"/-->
      <mesh filename="package://my_robot_model/urdf/meshes/Robot_Cover_Full.stl" scale="0.001 0.001 0.001"/>
    </geometry>
    <material name="Orange" />
  </visual>
  <collision>
    <!--origin xyz="0 0 0" rpy="0 0 0" /-->
    <origin xyz="0.0 0 -0.19125" rpy="0 0 -1.57" />
    <geometry>
      <!--cylinder length="0.35" radius="0.13"/-->
      <mesh filename="package://my_robot_model/urdf/meshes/Robot_Cover_Full.stl" scale="0.001 0.001 0.001"/>
    </geometry>
  </collision>
  </link>


  <!--========================================== ROBOT BODY JOINT ==========================================-->
  <joint name="robot_body_joint" type="fixed">
    <origin xyz="0 0 0.175" rpy="0 0 0" />
    <parent link="base_link" />
    <child link="robot_body_link" />
    <axis xyz="0 0 0" />
  </joint>


  <!--========================================== RIGHT WHEEL LINK ==========================================-->
  <link name="right_wheel_link">
    <inertial>
      <origin xyz="0.0 0.0 0.0" rpy="0 0 0" />
      <mass value="0.50917" />
      <inertia ixx="0.0012185" ixy="1.8059E-20" ixz="3.0427E-20" iyy="0.0012185" iyz="-4.0491E-20" izz="0.0022928" />
    </inertial>
    <visual>
      <origin xyz="0 0 0" rpy="0 0 0" />
      <geometry>
        <cylinder length="0.03" radius="0.04" />
      </geometry>
      <material name="Red" />
    </visual>
    <collision>
      <origin xyz="0 0 0" rpy="0 0 0" />
      <geometry>
        <cylinder length="0.03" radius="0.04" />
      </geometry>
    </collision>
  </link>

  <!--========================================== RIGHT WHEEL JOINT ==========================================-->
  <joint name="right_wheel_joint" type="continuous">
    <origin xyz="0.0 -0.12 0.01" rpy="1.571 0 0" />
    <parent link="base_link" />
    <child link="right_wheel_link" />
    <axis xyz="0 0 -1" />
  </joint>

  <transmission name="right_wheel_trans" type="SimpleTransmission">
    <type>transmission_interface/SimpleTransmission</type>
    <actuator name="right_wheel_motor">
      <mechanicalReduction>1</mechanicalReduction>
    </actuator>
    <joint name="right_wheel_joint">
      <hardwareInterface>VelocityJointInterface</hardwareInterface>
    </joint>
  </transmission>




  <!--========================================== LEFT WHEEL LINK ==========================================-->
  <link name="left_wheel_link">
    <inertial>
      <origin xyz="0.0 0.0 0.0" rpy="0 0 0" />
      <mass value="0.50917" />
      <inertia ixx="0.0012185" ixy="1.8059E-20" ixz="3.0427E-20" iyy="0.0012185" iyz="-4.0491E-20" izz="0.0022928" />
    </inertial>
    <visual>
      <origin xyz="0 0 0" rpy="0 0 0" />
      <geometry>
        <cylinder length="0.03" radius="0.04" />
      </geometry>
      <material name="Red" />
    </visual>
    <collision>
      <origin xyz="0 0 0" rpy="0 0 0" />
      <geometry>
        <cylinder length="0.03" radius="0.04" />
      </geometry>
    </collision>
  </link>

  <!--========================================== LEFT WHEEL JOINT ==========================================-->
  <joint name="left_wheel_joint" type="continuous">
    <origin xyz="0.0 0.12 0.01" rpy="-1.571 0 0" />
    <parent link="base_link" />
    <child link="left_wheel_link" />
    <axis xyz="0 0 1" />
  </joint>

  <transmission name="left_wheel_trans" type="SimpleTransmission">
    <type>transmission_interface/SimpleTransmission</type>
    <actuator name="left_wheel_motor">
      <mechanicalReduction>1</mechanicalReduction>
    </actuator>
    <joint name="left_wheel_joint">
      <hardwareInterface>VelocityJointInterface</hardwareInterface>
    </joint>
  </transmission>




  <!--=============================================== FRONT CASTOR WHEEL LINK ===============================================-->
  <link name="front_castor_wheel_link">
    <inertial>
      <origin xyz="0.0 0.0 0.0" rpy="0 0 0" />
      <mass value="0.50917" />
      <inertia ixx="0.0012185" ixy="1.8059E-20" ixz="3.0427E-20" iyy="0.0012185" iyz="-4.0491E-20" izz="0.0022928" />
    </inertial>
    <visual>
      <origin xyz="0 0 0" rpy="0 0 0" />
      <geometry>
        <sphere radius="0.03" />
      </geometry>
      <material name="Red" />
    </visual>
    <collision>
      <origin xyz="0 0 0" rpy="0 0 0" />
      <geometry>
        <sphere radius="0.03" />
      </geometry>
    </collision>
  </link>

  <!--============================================ FRONT CASTOR WHEEL JOINT ============================================-->
  <joint name="front_castor_wheel_joint" type="continuous">
    <origin xyz="0.07 0.0 0.0" rpy="0 0 0" />
    <parent link="base_link" />
    <child link="front_castor_wheel_link" />
    <axis xyz="0 1 1" />
  </joint>


  <!--=============================================== REAR CASTOR WHEEL LINK ===============================================-->
  <link name="rear_castor_wheel_link">
    <inertial>
      <origin xyz="0.0 0.0 0.0" rpy="0 0 0" />
      <mass value="0.50917" />
      <inertia ixx="0.0012185" ixy="1.8059E-20" ixz="3.0427E-20" iyy="0.0012185" iyz="-4.0491E-20" izz="0.0022928" />
    </inertial>
    <visual>
      <origin xyz="0 0 0" rpy="0 0 0" />
      <geometry>
        <sphere radius="0.03" />
      </geometry>
      <material name="Red" />
    </visual>
    <collision>
      <origin xyz="0 0 0" rpy="0 0 0" />
      <geometry>
        <sphere radius="0.03" />
      </geometry>
    </collision>
  </link>

  <!--============================================ REAR CASTOR WHEEL JOINT ============================================-->
  <joint name="rear_castor_wheel_joint" type="continuous">
    <origin xyz="-0.07 0.0 0.0" rpy="0 0 0" />
    <parent link="base_link" />
    <child link="rear_castor_wheel_link" />
    <axis xyz="0 1 1" />
  </joint>


  <!--========================================== LASER LINK ==========================================-->
  <link name="laser_link">
    <inertial>
      <origin xyz="0 0 0" rpy="0 0 0" />
      <mass value="0.0093378" />
      <inertia ixx="0" ixy="0" ixz="0" iyy="0" iyz="0" izz="0" /> 
    </inertial>
    <visual>
      <origin xyz="0 0 0" rpy="0 0 0" />
      <geometry>
        <cylinder length="0.046" radius="0.035" />
      </geometry>
      <material name="Green" />
    </visual>
    <collision>
      <origin xyz="0 0 0" rpy="0 0 0" />
      <geometry>
        <cylinder length="0.046" radius="0.035" />
      </geometry>
    </collision>
  </link>

  <!--========================================== LASER JOINT ==========================================-->
  <joint name="laser_joint" type="fixed">
    <origin xyz="0.0075 0.0 0.35" rpy="0 0 3.14" />
    <parent link="base_link" />
    <child link="laser_link" />
    <axis xyz="0 0 0" />
  </joint>


</robot>

